Workbook

Sheet Income Statement
A1: Suzlon Energy - Income Statement | C1: Historicals | F1: Forecasts
A2: Year ended 31 March | ₹ crore | Audited | C2: 45016 | D2: =DATE(YEAR(C2)+1,MONTH(C2),DAY(C2)) -> 45382 | E2: =DATE(YEAR(D2)+1,MONTH(D2),DAY(D2)) -> 45747 | F2: =DATE(YEAR(E2)+1,MONTH(E2),DAY(E2)) -> 46112 | G2: =DATE(YEAR(F2)+1,MONTH(F2),DAY(F2)) -> 46477 | H2: =DATE(YEAR(G2)+1,MONTH(G2),DAY(G2)) -> 46843 | I2: =DATE(YEAR(H2)+1,MONTH(H2),DAY(H2)) -> 47208 | J2: =DATE(YEAR(I2)+1,MONTH(I2),DAY(I2)) -> 47573
B4: Revenues
B5: Revenue from operations | C5: 3538.14 | D5: 5834.35 | E5: 10161.6 | F5: 15053.58 | G5: =(F5)*(1+G$33) -> 18365.368 | H5: =(G5)*(1+H$33) -> 21671.134 | I5: =(H5)*(1+I$33) -> 24705.092 | J5: =(I5)*(1+J$33) -> 27175.602
B6: Other operating income | C6: 52.3 | D6: 29.81 | E6: 36.12 | F6: 37.95 | G6: =(F6)*(1+G34) -> 39.8475 | H6: =(G6)*(1+H$33) -> 47.02005 | I6: =(H6)*(1+I$33) -> 53.602857 | J6: =(I6)*(1+J$33) -> 58.963143
B7: Total Revenues | C7: =SUM(C5, C6) -> 3590.44 | D7: =SUM(D5, D6) -> 5864.16 | E7: =SUM(E5, E6) -> 10197.72 | F7: =SUM(F5, F6) -> 15091.53 | G7: =SUM(G5:G6) -> 18405.215 | H7: =SUM(H5:H6) -> 21718.154 | I7: =SUM(I5:I6) -> 24758.695 | J7: =SUM(J5:J6) -> 27234.565
B9: Cost of Sales
B10: Consumption of raw materials, components consumed and services rendered | C10: 2662.97 | D10: 3767.73 | E10: 6986.89 | F10: 10590.21 | G10: =(G7*G$39)*($F$10/($F$10+$F$11)) -> 12920.43 | H10: =(H7*H$39)*($F$10/($F$10+$F$11)) -> 15246.107 | I10: =(I7*I$39)*($F$10/($F$10+$F$11)) -> 17380.562 | J10: =(J7*J$39)*($F$10/($F$10+$F$11)) -> 19118.618
B11: Changes in inventories of finished goods, semi-finished goods and work-in-progress | C11: 77.53 | D11: -32.09 | E11: -269.17 | F11: -482.72 | G11: =(G7*G$39)*($F$11/($F$10+$F$11)) -> -588.93542 | H11: =(H7*H$39)*($F$11/($F$10+$F$11)) -> -694.94379 | I11: =(I7*I$39)*($F$11/($F$10+$F$11)) -> -792.23592 | J11: =(J7*J$39)*($F$11/($F$10+$F$11)) -> -871.45952
B12: Employee benefits expense | C12: 252.51 | D12: 585.75 | E12: 791.75 | F12: 767.95 | G12: =G7*G40 -> 1472.4172 | H12: =H7*H40 -> 1737.4523 | I12: =I7*I40 -> 1980.6956 | J12: =J7*J40 -> 2178.7652
B13: Foreign exchange loss / gain | C13: 0 | D13: 8.28 | E13: 15.4 | F13: 54.38 | G13: =G7*G41 -> 46.013038 | H13: =H7*H41 -> 54.295385 | I13: =I7*I41 -> 61.896738 | J13: =J7*J41 -> 68.086412
B14: Other expenses | C14: 537.37 | D14: 623.58 | E14: 1008.59 | F14: 1339.9 | G14: =G7*G42 -> 1564.4433 | H14: =H7*H42 -> 1846.0431 | I14: =I7*I42 -> 2104.4891 | J14: =J7*J42 -> 2314.938
B15: Total Operating Cost | C15: =SUM(C10:C14) -> 3530.38 | D15: =SUM(D10:D14) -> 4953.25 | E15: =SUM(E10:E14) -> 8533.46 | F15: =SUM(F10:F14) -> 12269.72 | G15: =SUM(G10:G14) -> 15414.368 | H15: =SUM(H10:H14) -> 18188.954 | I15: =SUM(I10:I14) -> 20735.407 | J15: =SUM(J10:J14) -> 22808.948
B17: Gross Margin | C17: =C7-(C10+C11) -> 849.94 | D17: =D7-(D10+D11) -> 2128.52 | E17: =E7-(E10+E11) -> 3480 | F17: =F7-(F10+F11) -> 4984.04 | G17: =G7-(G10+G11) -> 6073.721 | H17: =H7-(H10+H11) -> 7166.9908 | I17: =I7-(I10+I11) -> 8170.3695 | J17: =J7-(J10+J11) -> 8987.4064
B18: SG&A Expense | C18: =SUM(C12, C14) -> 789.88 | D18: =SUM(D12, D14) -> 1209.33 | E18: =SUM(E12, E14) -> 1800.34 | F18: =SUM(F12, F14) -> 2107.85 | G18: =SUM(G12, G14) -> 3036.8605 | H18: =SUM(H12, H14) -> 3583.4954 | I18: =SUM(I12, I14) -> 4085.1847 | J18: =SUM(J12, J14) -> 4493.7032
B19: EBITDA | C19: =C17-C18 -> 60.06 | D19: =D17-D18 -> 919.19 | E19: =E17-E18 -> 1679.66 | F19: =F17-F18 -> 2876.19 | G19: =G17-G18 -> 3036.8605 | H19: =H17-H18 -> 3583.4954 | I19: =I17-I18 -> 4085.1847 | J19: =J17-J18 -> 4493.7032
B20: Depreciation and Amortisation | C20: 190.04 | D20: 141.53 | E20: 166.85 | F20: 189.65 | G20: ='Depreciation and Capex'!G6 -> 285.28083 | H20: ='Depreciation and Capex'!H6 -> 336.63138 | I20: ='Depreciation and Capex'!I6 -> 383.75978 | J20: ='Depreciation and Capex'!J6 -> 422.13576
B21: EBIT | C21: =C19-C20 -> -129.98 | D21: =D19-D20 -> 777.66 | E21: =E19-E20 -> 1512.81 | F21: =F19-F20 -> 2686.54 | G21: =G19-G20 -> 2751.5797 | H21: =H19-H20 -> 3246.864 | I21: =I19-I20 -> 3701.425 | J21: =J19-J20 -> 4071.5675
B22: Other Income | C22: 192.22 | D22: 47.37 | E22: 102.31 | F22: 154.13 | G22: =F22*1.07 -> 164.9191 | H22: =G22*1.07 -> 176.46344 | I22: =H22*1.07 -> 188.81588 | J22: =I22*1.07 -> 202.03299
B23: Exceptional items loss / gain | C23: 2542.08 | D23: 50.85 | E23: 102.86 | F23: 1178.4 | G23: =G7*G47 -> 920.26075 | H23: =H7*H47 -> 1085.9077 | I23: =I7*I47 -> 1237.9348 | J23: =J7*J47 -> 1361.7282
B24: Finance Cost | C24: 417.74 | D24: 228.86 | E24: 144.43 | F24: 441.56 | G24: 500 | H24: 500 | I24: 500 | J24: 500
B25: EBT | C25: =SUM(C21:C23)-C24 -> 2186.58 | D25: =SUM(D21:D23)-D24 -> 647.02 | E25: =SUM(E21:E23)-E24 -> 1573.55 | F25: =SUM(F21:F23)-F24 -> 3577.51 | G25: =SUM(G21:G23)-G24 -> 3336.7595 | H25: =SUM(H21:H23)-H24 -> 4009.2351 | I25: =SUM(I21:I23)-I24 -> 4628.1756 | J25: =SUM(J21:J23)-J24 -> 5135.3287
B26: Current tax | C26: 0 | D26: 0 | E26: 7.05 | F26: 0 | G26: 0 | H26: 0 | I26: 0 | J26: 0
B27: Deferred tax | C27: 0 | D27: 0 | E27: -645.1 | F27: -564.06 | G27: -500 | H27: -500 | I27: -500 | J27: -500
B28: Net Income | C28: =C25-C26-C27 -> 2186.58 | D28: =D25-D26-D27 -> 647.02 | E28: =E25-E26-E27 -> 2211.6 | F28: =F25-F26-F27 -> 4141.57 | G28: =G25-G26-G27 -> 3836.7595 | H28: =H25-H26-H27 -> 4509.2351 | I28: =I25-I26-I27 -> 5128.1756 | J28: =J25-J26-J27 -> 5635.3287
B31: Drivers
B32: Revenues
B33: Revenue from operations | D33: =(D5/C5)-1 -> 0.64898789 | E33: =(E5/D5)-1 -> 0.74168502 | F33: =(F5/E5)-1 -> 0.48141828 | G33: 0.22 | H33: 0.18 | I33: 0.14 | J33: 0.1
B34: Other operating income | D34: =(D6/C6)-1 -> -0.43001912 | E34: =(E6/D6)-1 -> 0.21167393 | F34: =(F6/E6)-1 -> 0.050664452 | G34: 0.05 | H34: 0.05 | I34: 0.05 | J34: 0.05
B35: Total Revenues | D35: =(D7/C7)-1 -> 0.63327057 | E35: =(E7/D7)-1 -> 0.73899075 | F35: =(F7/E7)-1 -> 0.47989256 | G35: =(G7/F7)-1 -> 0.21957251 | H35: =(H7/G7)-1 -> 0.18 | I35: =(I7/H7)-1 -> 0.14 | J35: =(J7/I7)-1 -> 0.1
B38: Cost of Sales
B39: Net Material Cost | C39: =(C10+C11)/C7 -> 0.76327692 | D39: =(D10+D11)/D7 -> 0.637029 | E39: =(E10+E11)/E7 -> 0.65874725 | F39: =(F10+F11)/F7 -> 0.66974588 | G39: 0.67 | H39: 0.67 | I39: 0.67 | J39: 0.67
B40: Employee benefits expense | C40: =C12/C7 -> 0.070328428 | D40: =D12/D7 -> 0.099886429 | E40: =E12/E7 -> 0.077639904 | F40: =F12/F7 -> 0.050886159 | G40: 0.08 | H40: 0.08 | I40: 0.08 | J40: 0.08
B41: Foreign exchange loss / gain | C41: =C13/C7 -> 0 | D41: =D13/D7 -> 0.0014119669 | E41: =E13/E7 -> 0.0015101415 | F41: =F13/F7 -> 0.0036033457 | G41: 0.0025 | H41: 0.0025 | I41: 0.0025 | J41: 0.0025
B42: Other expenses | C42: =C14/C7 -> 0.14966689 | D42: =D14/D7 -> 0.10633748 | E42: =E14/E7 -> 0.09890348 | F42: =F14/F7 -> 0.088784901 | G42: 0.085 | H42: 0.085 | I42: 0.085 | J42: 0.085
B43: Total Operating Cost
B45: Depreciation and Amortisation | D45: =(D20/C20)-1 -> -0.25526205 | E45: =(E20/D20)-1 -> 0.178902 | F45: =(F20/E20)-1 -> 0.13664969 | G45: 0.1 | H45: 0.1 | I45: 0.1 | J45: 0.1
B47: Exceptional items loss / gain | C47: =C23/C7 -> 0.7080135 | D47: =D23/D7 -> 0.0086713187 | E47: =E23/E7 -> 0.010086568 | F47: =F23/F7 -> 0.078083534 | G47: 0.05 | H47: 0.05 | I47: 0.05 | J47: 0.05
B61: Gross Margin | C61: =C17/C7 -> 0.23672308 | D61: =D17/D7 -> 0.362971 | E61: =E17/E7 -> 0.34125275 | F61: =F17/F7 -> 0.33025412
B62: EBITDA Margin | C62: =C19/C7 -> 0.016727755 | D62: =D19/D7 -> 0.15674709 | E62: =E19/E7 -> 0.16470937 | F62: =F19/F7 -> 0.19058306
...

Sheet Balance Sheet
A1: Suzlon Energy - Income Statement | C1: Historicals | F1: Forecasts
A2: Year ended 31 March | ₹ crore | Audited | C2: 45016 | D2: =DATE(YEAR(C2)+1,MONTH(C2),DAY(C2)) -> 45382 | E2: =DATE(YEAR(D2)+1,MONTH(D2),DAY(D2)) -> 45747 | F2: =DATE(YEAR(E2)+1,MONTH(E2),DAY(E2)) -> 46112 | G2: =DATE(YEAR(F2)+1,MONTH(F2),DAY(F2)) -> 46477 | H2: =DATE(YEAR(G2)+1,MONTH(G2),DAY(G2)) -> 46843 | I2: =DATE(YEAR(H2)+1,MONTH(H2),DAY(H2)) -> 47208 | J2: =DATE(YEAR(I2)+1,MONTH(I2),DAY(I2)) -> 47573
B4: Assets
B5: Non Current Assets
B6: Property, plant and equipment | C6: 425.07 | D6: 554.87 | E6: 579.31 | F6: 758.81 | G6: ='Depreciation and Capex'!G12 -> 1117.7117 | H6: ='Depreciation and Capex'!H12 -> 1541.2157 | I6: ='Depreciation and Capex'!I12 -> 2024.0103 | J6: ='Depreciation and Capex'!J12 -> 2555.0843
B7: Right-of-use assets | C7: 9.19 | D7: 35.62 | E7: 36.06 | F7: 293.96
B8: Capital work-in-progress | C8: 0.87 | D8: 4.28 | E8: 59.59 | F8: 137.88
B9: Investment properties | C9: 29.21 | D9: 27.01 | E9: 25.75 | F9: 24.19
B10: Goodwill | C10: 0 | D10: 0 | E10: 0 | F10: 0
B11: Intangible assets | C11: 62.9 | D11: 55.35 | E11: 91.35 | F11: 155.33
B12: Intangible assets under development | C12: 3.43 | D12: 3.51 | E12: 16.35 | F12: 13.57
B13: Financial assets — Investments | C13: 1753.9 | D13: 370.25 | E13: 1277.7 | F13: 2123.28
B14: Financial assets — Trade receivables | C14: 0 | D14: 0 | E14: 0 | F14: 217.31
B15: Financial assets — Loans | C15: 1244.42 | D15: 95.07 | E15: 139.06 | F15: 525.64
B16: Financial assets — Other financial assets | C16: 383.39 | D16: 871.82 | E16: 1062.67 | F16: 1179.9
B17: Deferred tax assets | C17: 0 | D17: 0 | E17: 638.05 | F17: 1202.11
B18: Other non-current assets | C18: 71.31 | D18: 72.61 | E18: 62.54 | F18: 30.2
B19: Total Non Current Assets | C19: =SUM(C6:C18) -> 3983.69 | D19: =SUM(D6:D18) -> 2090.39 | E19: =SUM(E6:E18) -> 3988.43 | F19: =SUM(F6:F18) -> 6662.18
B21: Current Assets
B22: Inventories | C22: 760.42 | D22: 2053.52 | E22: 2857.11 | F22: 3557.49
B23: Financial assets — Investments | C23: 1753.9 | D23: 8.35 | E23: 0 | F23: 213.89
B24: Financial assets — Trade receivables | C24: 546.32 | D24: 1658.56 | E24: 3682.9 | F24: 5741.95
B25: Cash and cash equivalents | C25: 290.63 | D25: 184.89 | E25: 808.02 | F25: 297.67
B26: Bank balances other than cash and cash equivalents | C26: 0 | D26: 177.27 | E26: 188.78 | F26: 575.27
B27: Financial assets — Loans | C27: 1244.42 | D27: 0.26 | E27: 0.27 | F27: 133.07
B28: Financial assets — Other financial assets | C28: 383.39 | D28: 153.67 | E28: 185.63 | F28: 201.99
B29: Current tax asset, net | C29: 0 | D29: 0 | E29: 49.68 | F29: 99.49
B30: Other current assets | C30: 363.01 | D30: 430.14 | E30: 583.64 | F30: 601.78
B31: Total Current Assets | C31: =SUM(C22:C30) -> 5342.09 | D31: =SUM(D22:D30) -> 4666.66 | E31: =SUM(E22:E30) -> 8356.03 | F31: =SUM(F22:F30) -> 11422.6
B33: Total Assets | C33: =SUM(C19, C31) -> 9325.78 | D33: =SUM(D19, D31) -> 6757.05 | E33: =SUM(E19, E31) -> 12344.46 | F33: =SUM(F19, F31) -> 18084.78
B35: Equity and liabilities
B36: Share capital | C36: 2454.4 | D36: 2721.72 | E36: 2731.79 | F36: 2744.99
B37: Other equity | C37: -1035.01 | D37: 559.47 | E37: 2797.21 | F37: 7082.76
B38: Total Equity | C38: =SUM(C36:C37) -> 1419.39 | D38: =SUM(D36:D37) -> 3281.19 | E38: =SUM(E36:E37) -> 5529 | F38: =SUM(F36:F37) -> 9827.75
B40: Non Current Liabilities
B41: Financial liabilities — Borrowings | C41: 2008.98 | D41: 0 | E41: 0 | F41: 0
B42: Financial liabilities — Lease liabilities | C42: 4.99 | D42: 14.5 | E42: 22.97 | F42: 261.11
B43: Other financial liabilities | C43: 3.39 | D43: 4.58 | E43: 617.94 | F43: 628.89
B44: Provisions | C44: 144.83 | D44: 163.41 | E44: 147.96 | F44: 207.51
B45: Other non-current liabilities | C45: 0.48 | D45: 0.48 | E45: 0.45 | F45: 0.09
...

Sheet Depreciation and Capex
A1: Suzlon Energy - Depreciation and Capex | C1: Historicals | F1: Forecasts
A2: Year ended 31 March | ₹ crore | C2: 45016 | D2: =DATE(YEAR(C2)+1,MONTH(C2),DAY(C2)) -> 45382 | E2: =DATE(YEAR(D2)+1,MONTH(D2),DAY(D2)) -> 45747 | F2: =DATE(YEAR(E2)+1,MONTH(E2),DAY(E2)) -> 46112 | G2: =DATE(YEAR(F2)+1,MONTH(F2),DAY(F2)) -> 46477 | H2: =DATE(YEAR(G2)+1,MONTH(G2),DAY(G2)) -> 46843 | I2: =DATE(YEAR(H2)+1,MONTH(H2),DAY(H2)) -> 47208 | J2: =DATE(YEAR(I2)+1,MONTH(I2),DAY(I2)) -> 47573
B4: Revenue | C4: ='Income Statement'!C7 -> 3590.44 | D4: ='Income Statement'!D7 -> 5864.16 | E4: ='Income Statement'!E7 -> 10197.72 | F4: ='Income Statement'!F7 -> 15091.53 | G4: ='Income Statement'!G7 -> 18405.215 | H4: ='Income Statement'!H7 -> 21718.154 | I4: ='Income Statement'!I7 -> 24758.695 | J4: ='Income Statement'!J7 -> 27234.565
B6: Depreciation and Amortisation | C6: ='Income Statement'!C20 -> 190.04 | D6: ='Income Statement'!D20 -> 141.53 | E6: ='Income Statement'!E20 -> 166.85 | F6: ='Income Statement'!F20 -> 189.65 | G6: =G4*G7 -> 285.28083 | H6: =H4*H7 -> 336.63138 | I6: =I4*I7 -> 383.75978 | J6: =J4*J7 -> 422.13576
B7: Depreciation and Amortisation % of Revenue | C7: =C6/C4 -> 0.052929446 | D7: =D6/D4 -> 0.024134744 | E7: =E6/E4 -> 0.0163615 | F7: =F6/F4 -> 0.012566652 | G7: 0.0155 | H7: 0.0155 | I7: 0.0155 | J7: 0.0155
B9: Beginning PP&E | G9: =F12 -> 758.81 | H9: =G12 -> 1117.7117 | I9: =H12 -> 1541.2157 | J9: =I12 -> 2024.0103
B10: Capital Expenditure | G10: =G4*0.035 -> 644.18253 | H10: =H4*0.035 -> 760.13538 | I10: =I4*0.035 -> 866.55434 | J10: =J4*0.035 -> 953.20977
B11: Depreciation and Amortisation | G11: =G6 -> 285.28083 | H11: =H6 -> 336.63138 | I11: =I6 -> 383.75978 | J11: =J6 -> 422.13576
B12: Net PPE | F12: ='Balance Sheet'!F6 -> 758.81 | G12: =G9+G10-G11 -> 1117.7117 | H12: =H9+H10-H11 -> 1541.2157 | I12: =I9+I10-I11 -> 2024.0103 | J12: =J9+J10-J11 -> 2555.0843

Sheet Working Capital
A1: Suzlon Energy - Working Capital | C1: Historicals | F1: Forecasts
A2: Year ended 31 March | ₹ crore | C2: 45016 | D2: =DATE(YEAR(C2)+1,MONTH(C2),DAY(C2)) -> 45382 | E2: =DATE(YEAR(D2)+1,MONTH(D2),DAY(D2)) -> 45747 | F2: =DATE(YEAR(E2)+1,MONTH(E2),DAY(E2)) -> 46112 | G2: =DATE(YEAR(F2)+1,MONTH(F2),DAY(F2)) -> 46477 | H2: =DATE(YEAR(G2)+1,MONTH(G2),DAY(G2)) -> 46843 | I2: =DATE(YEAR(H2)+1,MONTH(H2),DAY(H2)) -> 47208 | J2: =DATE(YEAR(I2)+1,MONTH(I2),DAY(I2)) -> 47573
B4: Working Capital Balances
B5: Trade receivables | C5: ='Balance Sheet'!C24 -> 546.32 | D5: ='Balance Sheet'!D24 -> 1658.56 | E5: ='Balance Sheet'!E24 -> 3682.9 | F5: ='Balance Sheet'!F24 -> 5741.95 | G5: =G9/G13 -> 6555.2821 | H5: =H9/H13 -> 7735.2329 | I5: =I9/I13 -> 8818.1655 | J5: =J9/J13 -> 9699.982
B6: Inventories | C6: ='Balance Sheet'!C22 -> 760.42 | D6: ='Balance Sheet'!D22 -> 2053.52 | E6: ='Balance Sheet'!E22 -> 2857.11 | F6: ='Balance Sheet'!F22 -> 3557.49 | G6: =G10/G14 -> 4645.4259 | H6: =H10/H14 -> 5481.6025 | I6: =I10/I14 -> 6249.0269 | J6: =J10/J14 -> 6873.9296
B7: Trade payables | C7: ='Balance Sheet'!C51+'Balance Sheet'!C52 -> 1062.09 | D7: ='Balance Sheet'!D51+'Balance Sheet'!D52 -> 2181.98 | E7: ='Balance Sheet'!E51+'Balance Sheet'!E52 -> 3333.2 | F7: ='Balance Sheet'!F51+'Balance Sheet'!F52 -> 4510.32 | G7: =G10/G15 -> 5912.3602 | H7: =H10/H15 -> 6976.585 | I7: =I10/I15 -> 7953.3069 | J7: =J10/J15 -> 8748.6376
L8: Days
B9: Total Revenues | C9: ='Income Statement'!C7 -> 3590.44 | D9: ='Income Statement'!D7 -> 5864.16 | E9: ='Income Statement'!E7 -> 10197.72 | F9: ='Income Statement'!F7 -> 15091.53 | G9: ='Income Statement'!G7 -> 18405.215 | H9: ='Income Statement'!H7 -> 21718.154 | I9: ='Income Statement'!I7 -> 24758.695 | J9: ='Income Statement'!J7 -> 27234.565 | L9: 365
B10: Operating Costs | C10: ='Income Statement'!C15 -> 3530.38 | D10: ='Income Statement'!D15 -> 4953.25 | E10: ='Income Statement'!E15 -> 8533.46 | F10: ='Income Statement'!F15 -> 12269.72 | G10: ='Income Statement'!G15 -> 15414.368 | H10: ='Income Statement'!H15 -> 18188.954 | I10: ='Income Statement'!I15 -> 20735.407 | J10: ='Income Statement'!J15 -> 22808.948
B12: Turnover Ratios
B13: Receivables turnover | C13: =C9/C5 -> 6.5720457 | D13: =D9/D5 -> 3.5356936 | E13: =E9/E5 -> 2.7689375 | F13: =F9/F5 -> 2.6282935 | G13: =$L$9/G17 -> 2.8076923 | H13: =$L$9/H17 -> 2.8076923 | I13: =$L$9/I17 -> 2.8076923 | J13: =$L$9/J17 -> 2.8076923
B14: Inventories turnover | C14: =C10/C6 -> 4.6426712 | D14: =D10/D6 -> 2.4120778 | E14: =E10/E6 -> 2.9867453 | F14: =F10/F6 -> 3.4489823 | G14: =$L$9/G18 -> 3.3181818 | H14: =$L$9/H18 -> 3.3181818 | I14: =$L$9/I18 -> 3.3181818 | J14: =$L$9/J18 -> 3.3181818
B15: Payable turnover | C15: =C10/C7 -> 3.3239933 | D15: =D10/D7 -> 2.2700712 | E15: =E10/E7 -> 2.5601404 | F15: =F10/F7 -> 2.7203657 | G15: =$L$9/G19 -> 2.6071429 | H15: =$L$9/H19 -> 2.6071429 | I15: =$L$9/I19 -> 2.6071429 | J15: =$L$9/J19 -> 2.6071429
B17: Receivables collection period | C17: =$L$9/C13 -> 55.538263 | D17: =$L$9/D13 -> 103.23293 | E17: =$L$9/E13 -> 131.81951 | F17: =$L$9/F13 -> 138.87338 | G17: 130 | H17: 130 | I17: 130 | J17: 130
B18: Inventory processing period | C18: =$L$9/C14 -> 78.618534 | D18: =$L$9/D14 -> 151.32182 | E18: =$L$9/E14 -> 122.2066 | F18: =$L$9/F14 -> 105.82832 | G18: 110 | H18: 110 | I18: 110 | J18: 110
B19: Payment period | C19: =$L$9/C15 -> 109.80768 | D19: =$L$9/D15 -> 160.78791 | E19: =$L$9/E15 -> 142.57031 | F19: =$L$9/F15 -> 134.17314 | G19: 140 | H19: 140 | I19: 140 | J19: 140
B20: Cash collection cycle | C20: =C17+C18-C19 -> 24.349113 | D20: =D17+D18-D19 -> 93.766839 | E20: =E17+E18-E19 -> 111.45581 | F20: =F17+F18-F19 -> 110.52856 | G20: =G17+G18-G19 -> 100 | H20: =H17+H18-H19 -> 100 | I20: =I17+I18-I19 -> 100 | J20: =J17+J18-J19 -> 100
